<?xml version="1.0"?>
<robot name="Mitsubishi-PA10"
       xmlns:xi="http://www.w3.org/2001/XInclude"
       xmlns:gazebo="http://playerstage.sourceforge.net/gazebo/xmlschema/#gz"
       xmlns:model="http://playerstage.sourceforge.net/gazebo/xmlschema/#model"
       xmlns:sensor="http://playerstage.sourceforge.net/gazebo/xmlschema/#sensor"
       xmlns:body="http://playerstage.sourceforge.net/gazebo/xmlschema/#body"
       xmlns:geom="http://playerstage.sourceforge.net/gazebo/xmlschema/#geom"
       xmlns:joint="http://playerstage.sourceforge.net/gazebo/xmlschema/#joint"
       xmlns:interface="http://playerstage.sourceforge.net/gazebo/xmlschema/#interface"
       xmlns:rendering="http://playerstage.sourceforge.net/gazebo/xmlschema/#rendering"
       xmlns:renderable="http://playerstage.sourceforge.net/gazebo/xmlschema/#renderable"
       xmlns:controller="http://playerstage.sourceforge.net/gazebo/xmlschema/#controller"
       xmlns:physics="http://playerstage.sourceforge.net/gazebo/xmlschema/#physics">
  <link name="link0">
    <visual>
      <origin xyz="0 0 0" rpy="0 -0 0"/>
      <geometry>
        <mesh filename="package://pa10_description/meshes/pa10/visual/link0_mesh.stl" scale="1 1 1" />
      </geometry>
    </visual>
    <collision>
      <origin xyz="0 0 0" rpy="0 -0 0"/>
      <geometry>
        <mesh filename="package://pa10_description/meshes/pa10/collision/link0_mesh.stl" scale="1 1 1" />
      </geometry>
    </collision>
    <inertial>
      <mass value="1" />
      <origin xyz="0 0 0" rpy="0 -0 0"/>
      <inertia ixx="1" ixy="0" ixz="0" iyy="1" iyz="0" izz="1"/>
    </inertial>
  </link>
  <gazebo reference="link0">
    <mu1>0.9</mu1>
    <mu2>0.9</mu2>
  </gazebo>
  <link name="link1">
    <visual>
      <origin xyz="0 0 0" rpy="0 -0 0"/>
      <geometry>
        <mesh filename="package://pa10_description/meshes/pa10/visual/link1_mesh.stl" scale="1 1 1" />
      </geometry>
    </visual>
    <collision>
      <origin xyz="0 0 0" rpy="0 -0 0"/>
      <geometry>
        <mesh filename="package://pa10_description/meshes/pa10/collision/link1_mesh.stl" scale="1 1 1" />
      </geometry>
    </collision>
    <inertial>
      <mass value="1" />
      <origin xyz="0 0 0" rpy="0 -0 0"/>
      <inertia ixx="1" ixy="0" ixz="0" iyy="1" iyz="0" izz="1"/>
    </inertial>
  </link>
  <gazebo reference="link1">
    <mu1>0.9</mu1>
    <mu2>0.9</mu2>
  </gazebo>
  <link name="link2">
    <visual>
      <origin xyz="0 0 0" rpy="0 -0 0"/>
      <geometry>
        <mesh filename="package://pa10_description/meshes/pa10/visual/link2_mesh.stl" scale="1 1 1" />
      </geometry>
    </visual>
    <collision>
      <origin xyz="0 0 0" rpy="0 -0 0"/>
      <geometry>
        <mesh filename="package://pa10_description/meshes/pa10/collision/link2_mesh.stl" scale="1 1 1" />
      </geometry>
    </collision>
    <inertial>
      <mass value="1" />
      <origin xyz="0 0 0" rpy="0 -0 0"/>
      <inertia ixx="1" ixy="0" ixz="0" iyy="1" iyz="0" izz="1"/>
    </inertial>
  </link>
  <gazebo reference="link2">
    <mu1>0.9</mu1>
    <mu2>0.9</mu2>
  </gazebo>
  <link name="link3">
    <visual>
      <origin xyz="0 0 0" rpy="0 -0 0"/>
      <geometry>
        <mesh filename="package://pa10_description/meshes/pa10/visual/link3_mesh.stl" scale="1 1 1" />
      </geometry>
    </visual>
    <collision>
      <origin xyz="0 0 0" rpy="0 -0 0"/>
      <geometry>
        <mesh filename="package://pa10_description/meshes/pa10/collision/link3_mesh.stl" scale="1 1 1" />
      </geometry>
    </collision>
    <inertial>
      <mass value="1" />
      <origin xyz="0 0 0" rpy="0 -0 0"/>
      <inertia ixx="1" ixy="0" ixz="0" iyy="1" iyz="0" izz="1"/>
    </inertial>
  </link>
  <gazebo reference="link3">
    <mu1>0.9</mu1>
    <mu2>0.9</mu2>
  </gazebo>
  <link name="link4">
    <visual>
      <origin xyz="0 0 0" rpy="0 -0 0"/>
      <geometry>
        <mesh filename="package://pa10_description/meshes/pa10/visual/link4_mesh.stl" scale="1 1 1" />
      </geometry>
    </visual>
    <collision>
      <origin xyz="0 0 0" rpy="0 -0 0"/>
      <geometry>
        <mesh filename="package://pa10_description/meshes/pa10/collision/link4_mesh.stl" scale="1 1 1" />
      </geometry>
    </collision>
    <inertial>
      <mass value="1" />
      <origin xyz="0 0 0" rpy="0 -0 0"/>
      <inertia ixx="1" ixy="0" ixz="0" iyy="1" iyz="0" izz="1"/>
    </inertial>
  </link>
  <gazebo reference="link4">
    <mu1>0.9</mu1>
    <mu2>0.9</mu2>
  </gazebo>
  <link name="link5">
    <visual>
      <origin xyz="0 0 0" rpy="0 -0 0"/>
      <geometry>
        <mesh filename="package://pa10_description/meshes/pa10/visual/link5_mesh.stl" scale="1 1 1" />
      </geometry>
    </visual>
    <collision>
      <origin xyz="0 0 0" rpy="0 -0 0"/>
      <geometry>
        <mesh filename="package://pa10_description/meshes/pa10/collision/link5_mesh.stl" scale="1 1 1" />
      </geometry>
    </collision>
    <inertial>
      <mass value="1" />
      <origin xyz="0 0 0" rpy="0 -0 0"/>
      <inertia ixx="1" ixy="0" ixz="0" iyy="1" iyz="0" izz="1"/>
    </inertial>
  </link>
  <gazebo reference="link5">
    <mu1>0.9</mu1>
    <mu2>0.9</mu2>
  </gazebo>
  <link name="link6">
    <visual>
      <origin xyz="0 0 0" rpy="0 -0 0"/>
      <geometry>
        <mesh filename="package://pa10_description/meshes/pa10/visual/link6_mesh.stl" scale="1 1 1" />
      </geometry>
    </visual>
    <collision>
      <origin xyz="0 0 0" rpy="0 -0 0"/>
      <geometry>
        <mesh filename="package://pa10_description/meshes/pa10/collision/link6_mesh.stl" scale="1 1 1" />
      </geometry>
    </collision>
    <inertial>
      <mass value="1" />
      <origin xyz="0 0 0" rpy="0 -0 0"/>
      <inertia ixx="1" ixy="0" ixz="0" iyy="1" iyz="0" izz="1"/>
    </inertial>
  </link>
  <gazebo reference="link6">
    <mu1>0.9</mu1>
    <mu2>0.9</mu2>
  </gazebo>
  <link name="link7">
    <visual>
      <origin xyz="0 0 1.35" rpy="0 -0 0"/>
      <geometry>
        <mesh filename="package://pa10_description/meshes/pa10/collision/link7_mesh.stl" scale="1 1 1" />
      </geometry>
    </visual>
    <collision>
      <origin xyz="0 0 1.35" rpy="0 -0 0"/>
      <geometry>
        <mesh filename="package://pa10_description/meshes/pa10/collision/link7_mesh.stl" scale="1 1 1" />
      </geometry>
    </collision>
    <inertial>
      <mass value="1" />
      <origin xyz="0 0 2.22045e-16" rpy="0 -0 0"/>
      <inertia ixx="1" ixy="0" ixz="0" iyy="1" iyz="0" izz="1"/>
    </inertial>
  </link>
  <gazebo reference="link7">
    <mu1>0.9</mu1>
    <mu2>0.9</mu2>
  </gazebo>
  <joint name="S1" type="revolute">
    <parent link="link0"/>
    <child  link="link1"/>
    <origin xyz="0 0 0" rpy="0 -0 0 "/>
    <axis   xyz="0 0 1"/>
    <limit lower="-3.08923" upper="3.08923" effort="100000" velocity="0.5" />
    <dynamics damping="0.2" friction="0" />
  </joint>
  <transmission type="pr2_mechanism_model/SimpleTransmission" name="S1_trans" >
    <actuator name="S1_motor" />
    <joint name="S1" />
    <mechanicalReduction>1</mechanicalReduction>
  </transmission>
  <gazebo reference="S1">
    <cfmDamping>0.4</cfmDamping>
  </gazebo>
  <joint name="S2" type="revolute">
    <parent link="link1"/>
    <child  link="link2"/>
    <origin xyz="0 0 0" rpy="0 -0 0 "/>
    <axis   xyz="0 1 0"/>
    <limit lower="-1.58825" upper="1.58825" effort="100000" velocity="0.5" />
    <dynamics damping="0.2" friction="0" />
  </joint>
  <transmission type="pr2_mechanism_model/SimpleTransmission" name="S2_trans" >
    <actuator name="S2_motor" />
    <joint name="S2" />
    <mechanicalReduction>1</mechanicalReduction>
  </transmission>
  <gazebo reference="S2">
    <cfmDamping>0.4</cfmDamping>
  </gazebo>
  <joint name="S3" type="revolute">
    <parent link="link2"/>
    <child  link="link3"/>
    <origin xyz="0 0 0" rpy="0 -0 0 "/>
    <axis   xyz="0 0 1"/>
    <limit lower="-3.03687" upper="3.03687" effort="100000" velocity="0.5" />
    <dynamics damping="0.2" friction="0" />
  </joint>
  <transmission type="pr2_mechanism_model/SimpleTransmission" name="S3_trans" >
    <actuator name="S3_motor" />
    <joint name="S3" />
    <mechanicalReduction>1</mechanicalReduction>
  </transmission>
  <gazebo reference="S3">
    <cfmDamping>0.4</cfmDamping>
  </gazebo>
  <joint name="E1" type="revolute">
    <parent link="link3"/>
    <child  link="link4"/>
    <origin xyz="0 0 0" rpy="0 -0 0 "/>
    <axis   xyz="0 1 0"/>
    <limit lower="-2.3911" upper="2.3911" effort="100000" velocity="0.5" />
    <dynamics damping="0.2" friction="0" />
  </joint>
  <transmission type="pr2_mechanism_model/SimpleTransmission" name="E1_trans" >
    <actuator name="E1_motor" />
    <joint name="E1" />
    <mechanicalReduction>1</mechanicalReduction>
  </transmission>
  <gazebo reference="E1">
    <cfmDamping>0.4</cfmDamping>
  </gazebo>
  <joint name="E2" type="revolute">
    <parent link="link4"/>
    <child  link="link5"/>
    <origin xyz="0 0 0" rpy="0 -0 0 "/>
    <axis   xyz="0 0 1"/>
    <limit lower="-4.45059" upper="4.45059" effort="100000" velocity="0.5" />
    <dynamics damping="0.2" friction="0" />
  </joint>
  <transmission type="pr2_mechanism_model/SimpleTransmission" name="E2_trans" >
    <actuator name="E2_motor" />
    <joint name="E2" />
    <mechanicalReduction>1</mechanicalReduction>
  </transmission>
  <gazebo reference="E2">
    <cfmDamping>0.4</cfmDamping>
  </gazebo>
  <joint name="W1" type="revolute">
    <parent link="link5"/>
    <child  link="link6"/>
    <origin xyz="0 0 0" rpy="0 -0 0 "/>
    <axis   xyz="0 1 0"/>
    <limit lower="-2.87979" upper="2.87979" effort="100000" velocity="0.5" />
    <dynamics damping="0.2" friction="0" />
  </joint>
  <transmission type="pr2_mechanism_model/SimpleTransmission" name="W1_trans" >
    <actuator name="W1_motor" />
    <joint name="W1" />
    <mechanicalReduction>1</mechanicalReduction>
  </transmission>
  <gazebo reference="W1">
    <cfmDamping>0.4</cfmDamping>
  </gazebo>
  <joint name="W2" type="continuous">
    <parent link="link6"/>
    <child  link="link7"/>
    <origin xyz="0 0 1.35" rpy="0 -0 0 "/>
    <axis   xyz="0 0 1"/>
    <limit lower="-3.14159" upper="3.14159" effort="100000" velocity="0.5" />
    <dynamics damping="0.2" friction="0" />
  </joint>
  <transmission type="pr2_mechanism_model/SimpleTransmission" name="W2_trans" >
    <actuator name="W2_motor" />
    <joint name="W2" />
    <mechanicalReduction>1</mechanicalReduction>
  </transmission>
  <gazebo reference="W2">
    <cfmDamping>0.4</cfmDamping>
  </gazebo>
</robot>
